<?xml version="1.0" encoding="utf-8"?>
<!-- This URDF was automatically created by SolidWorks to URDF Exporter! Originally created by
Stephen Brawner (brawner@gmail.com) 
     Commit Version: 1.6.0-4-g7f85cfe  Build Version: 1.6.7995.38578
     For more information, please see http://wiki.ros.org/sw_urdf_exporter -->
<robot
  name="robot_model_final">
  <!-- Base link -->
  <link
    name="base_link">
    <inertial>
      <origin
        xyz="6.12029265212874E-05 0.000108707800167779 -0.035069423573929"
        rpy="0 0 0" />
      <mass
        value="3" />
      <inertia
        ixx="0.00582740669898415"
        ixy="1.2136097657534E-07"
        ixz="-1.38070566679223E-05"
        iyy="0.00578431431397858"
        iyz="-5.32934605161888E-08"
        izz="0.0115147279955505" />
    </inertial>
    <visual>
      <origin
        xyz="0 0 0"
        rpy="0 0 0" />
      <geometry>
        <mesh
          filename="package://robot_model_final/meshes/base_link.STL" />
      </geometry>
      <material
        name="">
        <color
          rgba="0.752941176470588 0.752941176470588 0.752941176470588 1" />
      </material>
    </visual>
    <collision>
      <origin
        xyz="0 0 0"
        rpy="0 0 0" />
      <geometry>
        <mesh
          filename="package://robot_model_final/meshes/base_link.STL" />
      </geometry>
    </collision>
  </link>

  <!-- Banh xe phia truoc ben phai: Link and Joint -->
  <link
    name="r1_link">
    <inertial>
      <origin
        xyz="2.77555756156289E-17 1.44415729375069E-16 0.0318963396935971"
        rpy="0 0 0" />
      <mass
        value="1" />

      <inertia
        ixx="0.000164665684231058"
        ixy="6.69344493161661E-17"
        ixz="1.54302509693658E-16"
        iyy="0.000164665684230852"
        iyz="4.61155441429579E-17"
        izz="0.000205539151179695" />
    </inertial>
    <visual>
      <origin
        xyz="0 0 0"
        rpy="0 0 0" />
      <geometry>
        <mesh
          filename="package://robot_model_final/meshes/r1_link.STL" />
      </geometry>
      <material
        name="">
        <color
          rgba="0.752941176470588 0.752941176470588 0.752941176470588 1" />
      </material>
    </visual>
    <collision>
      <origin
        xyz="0 0 0"
        rpy="0 0 0" />
      <geometry>
        <mesh
          filename="package://robot_model_final/meshes/r1_link.STL" />
      </geometry>
    </collision>
  </link>
  <joint
    name="r1_joint"
    type="continuous">
    <origin
      xyz="-0.0918869559356422 0.19175 -0.0692209396075109"
      rpy="1.5708 0 0" />
    <parent
      link="base_link" />
    <child
      link="r1_link" />
    <axis
      xyz="0 0 1" />
    <!-- <dynamics
      damping="0.1"
      friction="0.8" /> -->
  </joint>
  <link
    name="r2_link">
    <inertial>
      <origin
        xyz="2.77555756156289E-17 3.22658566531686E-16 0.0332998499013895"
        rpy="0 0 0" />
      <mass
        value="1" />
      <inertia
        ixx="0.000141926294241648"
        ixy="-7.06425478010086E-18"
        ixz="-1.34039669834562E-16"
        iyy="0.000141926294241716"
        iyz="-7.01697770803214E-18"
        izz="0.000160542152522348" />
    </inertial>
    <visual>
      <origin
        xyz="0 0 0"
        rpy="0 0 0" />
      <geometry>
        <mesh
          filename="package://robot_model_final/meshes/r2_link.STL" />
      </geometry>
      <material
        name="">
        <color
          rgba="0.752941176470588 0.752941176470588 0.752941176470588 1" />
      </material>
    </visual>
    <collision>
      <origin
        xyz="0 0 0"
        rpy="0 0 0" />
      <geometry>
        <mesh
          filename="package://robot_model_final/meshes/r2_link.STL" />
      </geometry>
    </collision>
  </link>
  <joint
    name="r2_joint"
    type="continuous">
    <origin
      xyz="0.092218 0.19175 -0.068779"
      rpy="1.5708  0 0" />
    <!-- 0.22639 -->
    <parent
      link="base_link" />
    <child
      link="r2_link" />
    <axis
      xyz="0 0 1" />
    <!-- <dynamics
      damping="0.1"
      friction="0.8" /> -->
  </joint>
  <link
    name="l1_link">
    <inertial>
      <origin
        xyz="-2.42861286636753E-15 1.81972492629967E-15 -0.0332998499029291"
        rpy="0 0 0" />
      <mass
        value="1" />
      <inertia
        ixx="0.000141926294240933"
        ixy="-2.08889442100343E-17"
        ixz="1.78583132643176E-16"
        iyy="0.000141926294240951"
        iyz="2.95383417415828E-17"
        izz="0.000160542152521557" />
    </inertial>
    <visual>
      <origin
        xyz="0 0 0"
        rpy="0 0 0" />
      <geometry>
        <mesh
          filename="package://robot_model_final/meshes/l1_link.STL" />
      </geometry>
      <material
        name="">
        <color
          rgba="0.752941176470588 0.752941176470588 0.752941176470588 1" />
      </material>
    </visual>
    <collision>
      <origin
        xyz="0 0 0"
        rpy="0 0 0" />
      <geometry>
        <mesh
          filename="package://robot_model_final/meshes/l1_link.STL" />
      </geometry>
    </collision>
  </link>
  <joint
    name="l1_joint"
    type="continuous">
    <origin
      xyz="-0.091887 -0.19175 -0.069221"
      rpy="1.5708 0 0" />
    <parent
      link="base_link" />
    <child
      link="l1_link" />
    <axis
      xyz="0 0 1" />
    <!-- <dynamics
      damping="0.1"
      friction="0.8" /> -->
  </joint>
  <link
    name="l2_link">
    <inertial>
      <origin
        xyz="-7.63278329429795E-16 2.39391839684799E-15 -0.0311036603057481"
        rpy="0 0 0" />
      <mass
        value="1" />
      <inertia
        ixx="0.000164665684230644"
        ixy="-2.88836117431348E-17"
        ixz="-9.82439634202373E-17"
        iyy="0.000164665684230927"
        iyz="-9.22282295497188E-17"
        izz="0.000205539151179414" />
    </inertial>
    <visual>
      <origin
        xyz="0 0 0"
        rpy="0 0 0" />
      <geometry>
        <mesh
          filename="package://robot_model_final/meshes/l2_link.STL" />
      </geometry>
      <material
        name="">
        <color
          rgba="0.752941176470588 0.752941176470588 0.752941176470588 1" />
      </material>
    </visual>
    <collision>
      <origin
        xyz="0 0 0"
        rpy="0 0 0" />
      <geometry>
        <mesh
          filename="package://robot_model_final/meshes/l2_link.STL" />
      </geometry>
    </collision>
  </link>
  <joint
    name="l2_joint"
    type="continuous">
    <origin
      xyz="0.092218 -0.19175 -0.068779"
      rpy="1.5708 0 0" />
    <parent
      link="base_link" />
    <child
      link="l2_link" />
    <axis
      xyz="0 0 1" />
    <!-- <dynamics
      damping="0.1"
      friction="0.8" /> -->
  </joint>
  <link
    name="camera_link">
    <inertial>
      <origin
        xyz="-0.152512096291791 -0.00632735066538506 0.000436829896571737"
        rpy="0 0 0" />
      <mass
        value="0.00234451129545" />
      <inertia
        ixx="0.0542270178071188"
        ixy="0.000939736945780014"
        ixz="-0.00027029394647226"
        iyy="0.0268122928385178"
        iyz="9.80052751894619E-06"
        izz="0.0731544011306837" />
    </inertial>
    <visual>
      <origin
        xyz="0 0 0"
        rpy="0 0 0" />
      <geometry>
        <mesh
          filename="package://robot_model_final/meshes/camera_link.STL" />
      </geometry>
      <material
        name="">
        <color
          rgba="0.792156862745098 0.819607843137255 0.933333333333333 1" />
      </material>
    </visual>
    <collision>
      <origin
        xyz="0 0 0"
        rpy="0 0 0" />
      <geometry>
        <mesh
          filename="package://robot_model_final/meshes/camera_link.STL" />
      </geometry>
    </collision>
  </link>
  <joint
    name="camera_joint"
    type="fixed">
    <origin
      xyz="0.153621773993271 0.00624823378958103 -0.0505061004252008"
      rpy="0 0 0" />
    <parent
      link="base_link" />
    <child
      link="camera_link" />
    <axis
      xyz="0 0 0" />
    <dynamics
      damping="0.01"
      friction="0.01" />
  </joint>
  <link
    name="lidar_link">
    <inertial>
      <origin
        xyz="-0.00829409957033964 -1.38777878078145E-17 0.010701142222791"
        rpy="0 0 0" />
      <mass
        value="0.018336969016424" />
      <inertia
        ixx="1.94600350247756E-06"
        ixy="1.90897775740753E-22"
        ixz="-5.89556488554444E-07"
        iyy="3.42731242471714E-06"
        iyz="3.8014523688337E-22"
        izz="3.92757888361653E-06" />
    </inertial>
    <visual>
      <origin
        xyz="0 0 0"
        rpy="0 0 0" />
      <geometry>
        <mesh
          filename="package://robot_model_final/meshes/lidar_link.STL" />
      </geometry>
      <material
        name="">
        <color
          rgba="0.792156862745098 0.819607843137255 0.933333333333333 1" />
      </material>
    </visual>
    <collision>
      <origin
        xyz="0 0 0"
        rpy="0 0 0" />
      <geometry>
        <mesh
          filename="package://robot_model_final/meshes/lidar_link.STL" />
      </geometry>
    </collision>
  </link>
  <joint
    name="lidar_joint"
    type="fixed">
    <origin
      xyz="0.081426 0.0016541 0.010345"
      rpy="0 -0.0024023 0.00014479" />
    <parent
      link="base_link" />
    <child
      link="lidar_link" />
    <axis
      xyz="0 0 0" />
    <dynamics
      damping="0.01"
      friction="0.01" />
  </joint>
  <link
    name="imu_link">
    <inertial>
      <origin
        xyz="-0.0156688155118778 0.0104956315417902 0.0106839745884378"
        rpy="0 0 0" />
      <mass
        value="0.00100170070103827" />
      <inertia
        ixx="3.03937098435439E-08"
        ixy="1.30602732863116E-11"
        ixz="-3.82182226686084E-11"
        iyy="1.69531813594972E-08"
        iyz="3.13714257870475E-14"
        izz="4.63285990388826E-08" />
    </inertial>
    <visual>
      <origin
        xyz="0 0 0"
        rpy="0 0 0" />
      <geometry>
        <mesh
          filename="package://robot_model_final/meshes/imu_link.STL" />
      </geometry>
      <material
        name="">
        <color
          rgba="0.752941176470588 0.752941176470588 0.752941176470588 1" />
      </material>
    </visual>
    <collision>
      <origin
        xyz="0 0 0"
        rpy="0 0 0" />
      <geometry>
        <mesh
          filename="package://robot_model_final/meshes/imu_link.STL" />
      </geometry>
    </collision>
  </link>
  <joint
    name="imu_joint"
    type="fixed">
    <origin
      xyz="0.13613 -0.0020053 -0.0080599"
      rpy="0 0 0" />
    <parent
      link="base_link" />
    <child
      link="imu_link" />
    <axis
      xyz="0 0 0" />
    <dynamics
      damping="0.01"
      friction="0.01" />
  </joint>
  <link
    name="arm_link_1">
    <inertial>
      <origin
        xyz="-0.0112033450149954 0.0491263413995989 -0.00901913205749204"
        rpy="0 0 0" />
      <mass
        value="0.0100782671404842" />
      <inertia
        ixx="1.26950989861427E-05"
        ixy="2.79780182824188E-06"
        ixz="-1.03791120125071E-09"
        iyy="1.07547020502207E-06"
        iyz="2.82960366199418E-09"
        izz="1.37169259019842E-05" />
    </inertial>
    <visual>
      <origin
        xyz="0 0 0"
        rpy="0 0 0" />
      <geometry>
        <mesh
          filename="package://robot_model_final/meshes/arm_link_1.STL" />
      </geometry>
      <material
        name="">
        <color
          rgba="0.792156862745098 0.819607843137255 0.933333333333333 1" />
      </material>
    </visual>
    <collision>
      <origin
        xyz="0 0 0"
        rpy="0 0 0" />
      <geometry>
        <mesh
          filename="package://robot_model_final/meshes/arm_link_1.STL" />
      </geometry>
    </collision>
  </link>
  <joint
    name="arm_joint_1"
    type="revolute">
    <origin
      xyz="-4.2741E-05 -0.0089087 0.014"
      rpy="1.5708 0 0" />
    <parent
      link="base_link" />
    <child
      link="arm_link_1" />
    <axis
      xyz="0 0 -1" />
    <limit
      lower="-0.35"
      upper="0.35"
      effort="100"
      velocity="10" />
    <dynamics
      damping="0.01"
      friction="0.01" />
  </joint>
  <link
    name="arm_link_2">
    <inertial>
      <origin
        xyz="0.0569538942304978 0.00242153352607985 0.0179571892239791"
        rpy="0 0 0" />
      <mass
        value="0.0241822900190545" />
      <inertia
        ixx="1.72296770034613E-06"
        ixy="1.37452446217274E-08"
        ixz="-3.60461885129109E-08"
        iyy="1.12175606497327E-05"
        iyz="-2.87807320558505E-08"
        izz="1.11719252273331E-05" />
    </inertial>
    <visual>
      <origin
        xyz="0 0 0"
        rpy="0 0 0" />
      <geometry>
        <mesh
          filename="package://robot_model_final/meshes/arm_link_2.STL" />
      </geometry>
      <material
        name="">
        <color
          rgba="0.792156862745098 0.819607843137255 0.933333333333333 1" />
      </material>
    </visual>
    <collision>
      <origin
        xyz="0 0 0"
        rpy="0 0 0" />
      <geometry>
        <mesh
          filename="package://robot_model_final/meshes/arm_link_2.STL" />
      </geometry>
    </collision>
  </link>
  <joint
    name="arm_joint_2"
    type="revolute">
    <origin
      xyz="-0.022231 0.097493 -0.020023"
      rpy="0 0 0" />
    <parent
      link="arm_link_1" />
    <child
      link="arm_link_2" />
    <axis
      xyz="0 0 -1" />
    <limit
      lower="-0.35"
      upper="0.35"
      effort="100"
      velocity="10" />
    <dynamics
      damping="0.01"
      friction="0.01" />
  </joint>

  <!-- camera Plugin-->
  <gazebo reference="camera_link">
    <sensor name="camera" type="camera">
      <pose> 0 0 0 0 0 0 </pose>
      <visualize>true</visualize>
      <update_rate>10</update_rate>
      <camera>
        <horizontal_fov>1.089</horizontal_fov>
        <image>
          <format>R8G8B8</format>
          <width>640</width>
          <height>480</height>
        </image>
        <clip>
          <near>0.05</near>
          <far>8.0</far>
        </clip>
      </camera>
      <plugin name="camera_controller" filename="libgazebo_ros_camera.so">
        <frame_name>camera_link_optical</frame_name>
      </plugin>
    </sensor>
  </gazebo>

  <!-- Lidar plugin-->
  <gazebo reference="lidar_link">
    <sensor type="ray" name="lidar_sensor">
      <pose>0 0 0 0 0 0</pose>
      <visualize>true</visualize>
      <update_rate>10</update_rate>
      <ray>
        <scan>
          <horizontal>
            <samples>720</samples>
            <resolution>1</resolution>
            <min_angle>-2.356</min_angle>
            <max_angle>2.356</max_angle>
          </horizontal>
        </scan>
        <range>
          <min>0.1</min>
          <max>7.0</max>
          <resolution>0.01</resolution>
        </range>
      </ray>
      <plugin name="lidar_controller" filename="libgazebo_ros_laser.so">
        <topicName>/lidar/scan</topicName>
        <frameName>lidar_link</frameName>
      </plugin>
    </sensor>
  </gazebo>

  <!-- IMU plugin -->
  <gazebo reference="imu_link">
    <gravity>true</gravity>
    <sensor name="imu_sensor" type="imu">
      <always_on>true</always_on>
      <update_rate>10</update_rate>
      <visualize>true</visualize>
      <topic>__default_topic__</topic>
      <plugin filename="libgazebo_ros_imu_sensor.so" name="imu_plugin">
        <topicName>imu</topicName>
        <bodyName>imu_link</bodyName>
        <updateRateHZ>10.0</updateRateHZ>
        <frameName>imu_link</frameName>
        <initialOrientationAsReference>false</initialOrientationAsReference>
      </plugin>
      <pose>0 0 0 0 0 0</pose>
    </sensor>
  </gazebo>


  <!-- Add transmission cho 2 khớp tay máy và 4 khớp bánh xe-->

  <transmission name="wheel_l1_trasmission">
    <type>transmission_interface/SimpleTransmission</type>
    <joint name="l1_joint">
      <hardwareInterface>hardware_interface/VelocityJointInterface</hardwareInterface>
    </joint>
    <actuator name="l1_motor">
      <mechanicalReduction>1</mechanicalReduction>
    </actuator>
  </transmission>

  <transmission name="wheel_l2_trasmission">
    <type>transmission_interface/SimpleTransmission</type>
    <joint name="l2_joint">
      <hardwareInterface>hardware_interface/VelocityJointInterface</hardwareInterface>
    </joint>
    <actuator name="l2_motor">
      <mechanicalReduction>1</mechanicalReduction>
    </actuator>
  </transmission>

  <transmission name="wheel_r1_trasmission">
    <type>transmission_interface/SimpleTransmission</type>
    <joint name="r1_joint">
      <hardwareInterface>hardware_interface/VelocityJointInterface</hardwareInterface>
    </joint>
    <actuator name="r1_motor">
      <mechanicalReduction>1</mechanicalReduction>
    </actuator>
  </transmission>

  <transmission name="wheel_r2_trasmission">
    <type>transmission_interface/SimpleTransmission</type>
    <joint name="r2_joint">
      <hardwareInterface>hardware_interface/VelocityJointInterface</hardwareInterface>
    </joint>
    <actuator name="r2_motor">
      <mechanicalReduction>1</mechanicalReduction>
    </actuator>
  </transmission>

  <transmission name="arm_1_joint_transmission">
    <type>transmission_interface/SimpleTransmission</type>
    <joint name="arm_joint_1">
      <hardwareInterface>hardware_interface/PositionJointInterface</hardwareInterface>
    </joint>
    <actuator name="arm_motor_1">
      <mechanicalReduction>1.0</mechanicalReduction>
    </actuator>
  </transmission>

  <transmission name="arm_2_joint_transmission">
    <type>transmission_interface/SimpleTransmission</type>
    <joint name="arm_joint_2">
      <hardwareInterface>hardware_interface/PositionJointInterface</hardwareInterface>
    </joint>
    <actuator name="arm_motor_2">
      <mechanicalReduction>1.0</mechanicalReduction>
    </actuator>
  </transmission>


  <!-- ROS Control -->
  <gazebo>
    <plugin name="gazebo_ros_control" filename="libgazebo_ros_control.so">
    </plugin>
  </gazebo>


</robot>


<!-- Camera phía sau -->
<!-- <link name="camera_rear_link">
    <visual>
      <geometry>
        <box size="0.1 0.1 0.1" />  
      </geometry>
      <material name="Gazebo/Gray" />
    </visual>
    <inertial>
      <mass>0.1</mass>
      <origin xyz="0 0 0" />
      <inertia ixx="0.001" iyy="0.001" izz="0.001" ixy="0" ixz="0" iyz="0" />
    </inertial>
  </link>

  <joint name="camera_rear_joint" type="fixed">
    <parent link="base_link" />
    <child link="camera_rear_link" />
    <origin xyz="-0.1 0 0.1" rpy="0 0 3.14" /> 
  </joint>

  <gazebo reference="camera_rear_link">
    <sensor name="camera_rear" type="camera">
      <update_rate>30</update_rate>
      <camera>
        <horizontal_fov>1.396</horizontal_fov>
        <image>
          <width>640</width>
          <height>480</height>
          <format>R8G8B8</format>
        </image>
        <clip>
          <near>0.02</near>
          <far>100</far>
        </clip>
      </camera>
      <plugin name="gazebo_ros_camera" filename="libgazebo_ros_camera.so">
        <alwaysOn>true</alwaysOn>
        <updateRate>30.0</updateRate>
        <cameraName>rear_camera</cameraName>
        <imageTopicName>/rear_camera/image_raw</imageTopicName>
        <cameraInfoTopicName>/rear_camera/camera_info</cameraInfoTopicName>
        <frameName>camera_rear_link</frameName>
      </plugin>
    </sensor>
  </gazebo> -->
  