<sdf version='1.7'>
  <world name='default'>
    <light name='sun' type='directional'>
      <cast_shadows>1</cast_shadows>
      <pose>0 0 10 0 -0 0</pose>
      <diffuse>0.8 0.8 0.8 1</diffuse>
      <specular>0.2 0.2 0.2 1</specular>
      <attenuation>
        <range>1000</range>
        <constant>0.9</constant>
        <linear>0.01</linear>
        <quadratic>0.001</quadratic>
      </attenuation>
      <direction>-0.5 0.1 -0.9</direction>
      <spot>
        <inner_angle>0</inner_angle>
        <outer_angle>0</outer_angle>
        <falloff>0</falloff>
      </spot>
    </light>
    <model name='ground_plane'>
      <static>1</static>
      <link name='link'>
        <collision name='collision'>
          <geometry>
            <plane>
              <normal>0 0 1</normal>
              <size>100 100</size>
            </plane>
          </geometry>
          <surface>
            <contact>
              <collide_bitmask>65535</collide_bitmask>
              <ode/>
            </contact>
            <friction>
              <ode>
                <mu>100</mu>
                <mu2>50</mu2>
              </ode>
              <torsional>
                <ode/>
              </torsional>
            </friction>
            <bounce/>
          </surface>
          <max_contacts>10</max_contacts>
        </collision>
        <visual name='visual'>
          <cast_shadows>0</cast_shadows>
          <geometry>
            <plane>
              <normal>0 0 1</normal>
              <size>100 100</size>
            </plane>
          </geometry>
          <material>
            <script>
              <uri>file://media/materials/scripts/gazebo.material</uri>
              <name>Gazebo/Grey</name>
            </script>
          </material>
        </visual>
        <self_collide>0</self_collide>
        <enable_wind>0</enable_wind>
        <kinematic>0</kinematic>
      </link>
    </model>
    <gravity>0 0 -9.8</gravity>
    <magnetic_field>6e-06 2.3e-05 -4.2e-05</magnetic_field>
    <atmosphere type='adiabatic'/>
    <physics type='ode'>
      <max_step_size>0.001</max_step_size>
      <real_time_factor>1</real_time_factor>
      <real_time_update_rate>1000</real_time_update_rate>
    </physics>
    <scene>
      <ambient>0.4 0.4 0.4 1</ambient>
      <background>0.7 0.7 0.7 1</background>
      <shadows>1</shadows>
    </scene>
    <wind/>
    <spherical_coordinates>
      <surface_model>EARTH_WGS84</surface_model>
      <latitude_deg>0</latitude_deg>
      <longitude_deg>0</longitude_deg>
      <elevation>0</elevation>
      <heading_deg>0</heading_deg>
    </spherical_coordinates>
    <model name='robot_model_final'>
      <link name='base_link'>
        <inertial>
          <pose>0.000352 0.000116 -0.034864 0 -0 0</pose>
          <mass>5.02168</mass>
          <inertia>
            <ixx>0.060116</ixx>
            <ixy>0.00093679</ixy>
            <ixz>-0.00036404</ixz>
            <iyy>0.0327714</iyy>
            <iyz>7.84313e-06</iyz>
            <izz>0.0847851</izz>
          </inertia>
        </inertial>
        <collision name='base_link_collision'>
          <pose>0 0 0 0 -0 0</pose>
          <geometry>
            <mesh>
              <scale>1 1 1</scale>
              <uri>/home/doan/catkin_ws/src/robot_model_final/meshes/base_link.STL</uri>
            </mesh>
          </geometry>
          <max_contacts>10</max_contacts>
          <surface>
            <contact>
              <ode/>
            </contact>
            <bounce/>
            <friction>
              <torsional>
                <ode/>
              </torsional>
              <ode/>
            </friction>
          </surface>
        </collision>
        <collision name='base_link_fixed_joint_lump__camera_link_collision_1'>
          <pose>0.153622 0.006248 -0.050506 0 -0 0</pose>
          <geometry>
            <mesh>
              <scale>1 1 1</scale>
              <uri>/home/doan/catkin_ws/src/robot_model_final/meshes/camera_link.STL</uri>
            </mesh>
          </geometry>
          <surface>
            <contact>
              <ode/>
            </contact>
            <friction>
              <ode/>
              <torsional>
                <ode/>
              </torsional>
            </friction>
            <bounce/>
          </surface>
          <max_contacts>10</max_contacts>
        </collision>
        <collision name='base_link_fixed_joint_lump__imu_link_collision_2'>
          <pose>0.13613 -0.002005 -0.00806 0 -0 0</pose>
          <geometry>
            <mesh>
              <scale>1 1 1</scale>
              <uri>/home/doan/catkin_ws/src/robot_model_final/meshes/imu_link.STL</uri>
            </mesh>
          </geometry>
          <surface>
            <contact>
              <ode/>
            </contact>
            <friction>
              <ode/>
              <torsional>
                <ode/>
              </torsional>
            </friction>
            <bounce/>
          </surface>
          <max_contacts>10</max_contacts>
        </collision>
        <collision name='base_link_fixed_joint_lump__lidar_link_collision_3'>
          <pose>0.081426 0.001654 0.010345 0 -0.002402 0.000145</pose>
          <geometry>
            <mesh>
              <scale>1 1 1</scale>
              <uri>/home/doan/catkin_ws/src/robot_model_final/meshes/lidar_link.STL</uri>
            </mesh>
          </geometry>
          <surface>
            <contact>
              <ode/>
            </contact>
            <friction>
              <ode/>
              <torsional>
                <ode/>
              </torsional>
            </friction>
            <bounce/>
          </surface>
          <max_contacts>10</max_contacts>
        </collision>
        <visual name='base_link_visual'>
          <pose>0 0 0 0 -0 0</pose>
          <geometry>
            <mesh>
              <scale>1 1 1</scale>
              <uri>/home/doan/catkin_ws/src/robot_model_final/meshes/base_link.STL</uri>
            </mesh>
          </geometry>
        </visual>
        <visual name='base_link_fixed_joint_lump__camera_link_visual_1'>
          <pose>0.153622 0.006248 -0.050506 0 -0 0</pose>
          <geometry>
            <mesh>
              <scale>1 1 1</scale>
              <uri>/home/doan/catkin_ws/src/robot_model_final/meshes/camera_link.STL</uri>
            </mesh>
          </geometry>
        </visual>
        <visual name='base_link_fixed_joint_lump__imu_link_visual_2'>
          <pose>0.13613 -0.002005 -0.00806 0 -0 0</pose>
          <geometry>
            <mesh>
              <scale>1 1 1</scale>
              <uri>/home/doan/catkin_ws/src/robot_model_final/meshes/imu_link.STL</uri>
            </mesh>
          </geometry>
        </visual>
        <visual name='base_link_fixed_joint_lump__lidar_link_visual_3'>
          <pose>0.081426 0.001654 0.010345 0 -0.002402 0.000145</pose>
          <geometry>
            <mesh>
              <scale>1 1 1</scale>
              <uri>/home/doan/catkin_ws/src/robot_model_final/meshes/lidar_link.STL</uri>
            </mesh>
          </geometry>
        </visual>
        <sensor name='camera' type='camera'>
          <visualize>1</visualize>
          <update_rate>10</update_rate>
          <camera>
            <horizontal_fov>1.089</horizontal_fov>
            <image>
              <format>R8G8B8</format>
              <width>640</width>
              <height>480</height>
            </image>
            <clip>
              <near>0.05</near>
              <far>8</far>
            </clip>
          </camera>
          <plugin name='camera_controller' filename='libgazebo_ros_camera.so'>
            <frame_name>camera_link_optical</frame_name>
            <robotNamespace>/</robotNamespace>
          </plugin>
          <pose>0.153622 0.006248 -0.050506 0 -0 0</pose>
        </sensor>
        <gravity>1</gravity>
        <sensor name='imu_sensor' type='imu'>
          <always_on>1</always_on>
          <update_rate>10</update_rate>
          <visualize>1</visualize>
          <topic>__default_topic__</topic>
          <plugin name='imu_plugin' filename='libgazebo_ros_imu_sensor.so'>
            <topicName>imu</topicName>
            <bodyName>imu_link</bodyName>
            <updateRateHZ>10.0</updateRateHZ>
            <frameName>imu_link</frameName>
            <initialOrientationAsReference>0</initialOrientationAsReference>
            <robotNamespace>/</robotNamespace>
          </plugin>
          <pose>0.13613 -0.002005 -0.00806 0 -0 0</pose>
          <imu/>
        </sensor>
        <sensor name='lidar_sensor' type='ray'>
          <visualize>1</visualize>
          <update_rate>10</update_rate>
          <ray>
            <scan>
              <horizontal>
                <samples>720</samples>
                <resolution>1</resolution>
                <min_angle>-2.356</min_angle>
                <max_angle>2.356</max_angle>
              </horizontal>
              <vertical>
                <samples>1</samples>
                <min_angle>0</min_angle>
                <max_angle>0</max_angle>
              </vertical>
            </scan>
            <range>
              <min>0.1</min>
              <max>7</max>
              <resolution>0.01</resolution>
            </range>
          </ray>
          <plugin name='lidar_controller' filename='libgazebo_ros_laser.so'>
            <topicName>/lidar/scan</topicName>
            <frameName>lidar_link</frameName>
            <robotNamespace>/</robotNamespace>
          </plugin>
          <pose>0.081426 0.001654 0.010345 0 -0.002402 0.000145</pose>
        </sensor>
        <self_collide>0</self_collide>
        <enable_wind>0</enable_wind>
        <kinematic>0</kinematic>
      </link>
      <joint name='arm_joint_1' type='revolute'>
        <pose relative_to='base_link'>-4.3e-05 -0.008909 0.014 1.5708 -0 0</pose>
        <parent>base_link</parent>
        <child>arm_link_1</child>
        <axis>
          <xyz>0 0 -1</xyz>
          <limit>
            <lower>-0.35</lower>
            <upper>0.35</upper>
            <effort>100</effort>
            <velocity>10</velocity>
          </limit>
          <dynamics>
            <damping>0.01</damping>
            <friction>0.01</friction>
            <spring_reference>0</spring_reference>
            <spring_stiffness>0</spring_stiffness>
          </dynamics>
        </axis>
      </joint>
      <link name='arm_link_1'>
        <pose relative_to='arm_joint_1'>0 0 0 0 -0 0</pose>
        <inertial>
          <pose>-0.011203 0.049126 -0.009019 0 -0 0</pose>
          <mass>0.0100783</mass>
          <inertia>
            <ixx>1.26951e-05</ixx>
            <ixy>2.7978e-06</ixy>
            <ixz>-1.03791e-09</ixz>
            <iyy>1.07547e-06</iyy>
            <iyz>2.8296e-09</iyz>
            <izz>1.37169e-05</izz>
          </inertia>
        </inertial>
        <collision name='arm_link_1_collision'>
          <pose>0 0 0 0 -0 0</pose>
          <geometry>
            <mesh>
              <scale>1 1 1</scale>
              <uri>/home/doan/catkin_ws/src/robot_model_final/meshes/arm_link_1.STL</uri>
            </mesh>
          </geometry>
          <max_contacts>10</max_contacts>
          <surface>
            <contact>
              <ode/>
            </contact>
            <bounce/>
            <friction>
              <torsional>
                <ode/>
              </torsional>
              <ode/>
            </friction>
          </surface>
        </collision>
        <visual name='arm_link_1_visual'>
          <pose>0 0 0 0 -0 0</pose>
          <geometry>
            <mesh>
              <scale>1 1 1</scale>
              <uri>/home/doan/catkin_ws/src/robot_model_final/meshes/arm_link_1.STL</uri>
            </mesh>
          </geometry>
        </visual>
        <self_collide>0</self_collide>
        <enable_wind>0</enable_wind>
        <kinematic>0</kinematic>
      </link>
      <joint name='arm_joint_2' type='revolute'>
        <pose relative_to='arm_link_1'>-0.022231 0.097493 -0.020023 0 -0 0</pose>
        <parent>arm_link_1</parent>
        <child>arm_link_2</child>
        <axis>
          <xyz>0 0 -1</xyz>
          <limit>
            <lower>-0.35</lower>
            <upper>0.35</upper>
            <effort>100</effort>
            <velocity>10</velocity>
          </limit>
          <dynamics>
            <damping>0.01</damping>
            <friction>0.01</friction>
            <spring_reference>0</spring_reference>
            <spring_stiffness>0</spring_stiffness>
          </dynamics>
        </axis>
      </joint>
      <link name='arm_link_2'>
        <pose relative_to='arm_joint_2'>0 0 0 0 -0 0</pose>
        <inertial>
          <pose>0.056954 0.002422 0.017957 0 -0 0</pose>
          <mass>0.0241823</mass>
          <inertia>
            <ixx>1.72297e-06</ixx>
            <ixy>1.37452e-08</ixy>
            <ixz>-3.60462e-08</ixz>
            <iyy>1.12176e-05</iyy>
            <iyz>-2.87807e-08</iyz>
            <izz>1.11719e-05</izz>
          </inertia>
        </inertial>
        <collision name='arm_link_2_collision'>
          <pose>0 0 0 0 -0 0</pose>
          <geometry>
            <mesh>
              <scale>1 1 1</scale>
              <uri>/home/doan/catkin_ws/src/robot_model_final/meshes/arm_link_2.STL</uri>
            </mesh>
          </geometry>
          <max_contacts>10</max_contacts>
          <surface>
            <contact>
              <ode/>
            </contact>
            <bounce/>
            <friction>
              <torsional>
                <ode/>
              </torsional>
              <ode/>
            </friction>
          </surface>
        </collision>
        <visual name='arm_link_2_visual'>
          <pose>0 0 0 0 -0 0</pose>
          <geometry>
            <mesh>
              <scale>1 1 1</scale>
              <uri>/home/doan/catkin_ws/src/robot_model_final/meshes/arm_link_2.STL</uri>
            </mesh>
          </geometry>
        </visual>
        <self_collide>0</self_collide>
        <enable_wind>0</enable_wind>
        <kinematic>0</kinematic>
      </link>
      <joint name='l1_joint' type='revolute'>
        <pose relative_to='base_link'>-0.091887 -0.19175 -0.069221 1.5708 -0 0</pose>
        <parent>base_link</parent>
        <child>l1_link</child>
        <axis>
          <xyz>0 0 1</xyz>
          <limit>
            <lower>-1e+16</lower>
            <upper>1e+16</upper>
          </limit>
          <dynamics>
            <spring_reference>0</spring_reference>
            <spring_stiffness>0</spring_stiffness>
          </dynamics>
        </axis>
      </joint>
      <link name='l1_link'>
        <pose relative_to='l1_joint'>0 0 0 0 -0 0</pose>
        <inertial>
          <pose>-0 0 -0.0333 0 -0 0</pose>
          <mass>2</mass>
          <inertia>
            <ixx>0.000141926</ixx>
            <ixy>-2.08889e-17</ixy>
            <ixz>1.78583e-16</ixz>
            <iyy>0.000141926</iyy>
            <iyz>2.95383e-17</iyz>
            <izz>0.000160542</izz>
          </inertia>
        </inertial>
        <collision name='l1_link_collision'>
          <pose>0 0 0 0 -0 0</pose>
          <geometry>
            <mesh>
              <scale>1 1 1</scale>
              <uri>/home/doan/catkin_ws/src/robot_model_final/meshes/l1_link.STL</uri>
            </mesh>
          </geometry>
          <max_contacts>10</max_contacts>
          <surface>
            <contact>
              <ode/>
            </contact>
            <bounce/>
            <friction>
              <torsional>
                <ode/>
              </torsional>
              <ode/>
            </friction>
          </surface>
        </collision>
        <visual name='l1_link_visual'>
          <pose>0 0 0 0 -0 0</pose>
          <geometry>
            <mesh>
              <scale>1 1 1</scale>
              <uri>/home/doan/catkin_ws/src/robot_model_final/meshes/l1_link.STL</uri>
            </mesh>
          </geometry>
        </visual>
        <self_collide>0</self_collide>
        <enable_wind>0</enable_wind>
        <kinematic>0</kinematic>
      </link>
      <joint name='l2_joint' type='revolute'>
        <pose relative_to='base_link'>0.092218 -0.19175 -0.068779 1.5708 -0 0</pose>
        <parent>base_link</parent>
        <child>l2_link</child>
        <axis>
          <xyz>0 0 1</xyz>
          <limit>
            <lower>-1e+16</lower>
            <upper>1e+16</upper>
          </limit>
          <dynamics>
            <spring_reference>0</spring_reference>
            <spring_stiffness>0</spring_stiffness>
          </dynamics>
        </axis>
      </joint>
      <link name='l2_link'>
        <pose relative_to='l2_joint'>0 0 0 0 -0 0</pose>
        <inertial>
          <pose>-0 0 -0.031104 0 -0 0</pose>
          <mass>2</mass>
          <inertia>
            <ixx>0.000164666</ixx>
            <ixy>-2.88836e-17</ixy>
            <ixz>-9.8244e-17</ixz>
            <iyy>0.000164666</iyy>
            <iyz>-9.22282e-17</iyz>
            <izz>0.000205539</izz>
          </inertia>
        </inertial>
        <collision name='l2_link_collision'>
          <pose>0 0 0 0 -0 0</pose>
          <geometry>
            <mesh>
              <scale>1 1 1</scale>
              <uri>/home/doan/catkin_ws/src/robot_model_final/meshes/l2_link.STL</uri>
            </mesh>
          </geometry>
          <max_contacts>10</max_contacts>
          <surface>
            <contact>
              <ode/>
            </contact>
            <bounce/>
            <friction>
              <torsional>
                <ode/>
              </torsional>
              <ode/>
            </friction>
          </surface>
        </collision>
        <visual name='l2_link_visual'>
          <pose>0 0 0 0 -0 0</pose>
          <geometry>
            <mesh>
              <scale>1 1 1</scale>
              <uri>/home/doan/catkin_ws/src/robot_model_final/meshes/l2_link.STL</uri>
            </mesh>
          </geometry>
        </visual>
        <self_collide>0</self_collide>
        <enable_wind>0</enable_wind>
        <kinematic>0</kinematic>
      </link>
      <joint name='r1_joint' type='revolute'>
        <pose relative_to='base_link'>-0.091887 0.19175 -0.069221 1.5708 -0 0</pose>
        <parent>base_link</parent>
        <child>r1_link</child>
        <axis>
          <xyz>0 0 1</xyz>
          <limit>
            <lower>-1e+16</lower>
            <upper>1e+16</upper>
          </limit>
          <dynamics>
            <spring_reference>0</spring_reference>
            <spring_stiffness>0</spring_stiffness>
          </dynamics>
        </axis>
      </joint>
      <link name='r1_link'>
        <pose relative_to='r1_joint'>0 0 0 0 -0 0</pose>
        <inertial>
          <pose>0 0 0.031896 0 -0 0</pose>
          <mass>2</mass>
          <inertia>
            <ixx>0.000164666</ixx>
            <ixy>6.69344e-17</ixy>
            <ixz>1.54303e-16</ixz>
            <iyy>0.000164666</iyy>
            <iyz>4.61155e-17</iyz>
            <izz>0.000205539</izz>
          </inertia>
        </inertial>
        <collision name='r1_link_collision'>
          <pose>0 0 0 0 -0 0</pose>
          <geometry>
            <mesh>
              <scale>1 1 1</scale>
              <uri>/home/doan/catkin_ws/src/robot_model_final/meshes/r1_link.STL</uri>
            </mesh>
          </geometry>
          <max_contacts>10</max_contacts>
          <surface>
            <contact>
              <ode/>
            </contact>
            <bounce/>
            <friction>
              <torsional>
                <ode/>
              </torsional>
              <ode/>
            </friction>
          </surface>
        </collision>
        <visual name='r1_link_visual'>
          <pose>0 0 0 0 -0 0</pose>
          <geometry>
            <mesh>
              <scale>1 1 1</scale>
              <uri>/home/doan/catkin_ws/src/robot_model_final/meshes/r1_link.STL</uri>
            </mesh>
          </geometry>
        </visual>
        <self_collide>0</self_collide>
        <enable_wind>0</enable_wind>
        <kinematic>0</kinematic>
      </link>
      <joint name='r2_joint' type='revolute'>
        <pose relative_to='base_link'>0.092218 0.19175 -0.068779 1.5708 -0 0</pose>
        <parent>base_link</parent>
        <child>r2_link</child>
        <axis>
          <xyz>0 0 1</xyz>
          <limit>
            <lower>-1e+16</lower>
            <upper>1e+16</upper>
          </limit>
          <dynamics>
            <spring_reference>0</spring_reference>
            <spring_stiffness>0</spring_stiffness>
          </dynamics>
        </axis>
      </joint>
      <link name='r2_link'>
        <pose relative_to='r2_joint'>0 0 0 0 -0 0</pose>
        <inertial>
          <pose>0 0 0.0333 0 -0 0</pose>
          <mass>2</mass>
          <inertia>
            <ixx>0.000141926</ixx>
            <ixy>-7.06425e-18</ixy>
            <ixz>-1.3404e-16</ixz>
            <iyy>0.000141926</iyy>
            <iyz>-7.01698e-18</iyz>
            <izz>0.000160542</izz>
          </inertia>
        </inertial>
        <collision name='r2_link_collision'>
          <pose>0 0 0 0 -0 0</pose>
          <geometry>
            <mesh>
              <scale>1 1 1</scale>
              <uri>/home/doan/catkin_ws/src/robot_model_final/meshes/r2_link.STL</uri>
            </mesh>
          </geometry>
          <max_contacts>10</max_contacts>
          <surface>
            <contact>
              <ode/>
            </contact>
            <bounce/>
            <friction>
              <torsional>
                <ode/>
              </torsional>
              <ode/>
            </friction>
          </surface>
        </collision>
        <visual name='r2_link_visual'>
          <pose>0 0 0 0 -0 0</pose>
          <geometry>
            <mesh>
              <scale>1 1 1</scale>
              <uri>/home/doan/catkin_ws/src/robot_model_final/meshes/r2_link.STL</uri>
            </mesh>
          </geometry>
        </visual>
        <self_collide>0</self_collide>
        <enable_wind>0</enable_wind>
        <kinematic>0</kinematic>
      </link>
      <plugin name='gazebo_ros_control' filename='libgazebo_ros_control.so'>
        <robotNamespace>/</robotNamespace>
        <robotSimType>gazebo_ros_control/DefaultRobotHWSim</robotSimType>
        <legacyModeNS>1</legacyModeNS>
        <controlPeriod>0.001</controlPeriod>
      </plugin>
      <frame name='camera_joint' attached_to='base_link'>
        <pose>0.153622 0.006248 -0.050506 0 -0 0</pose>
      </frame>
      <frame name='camera_link' attached_to='camera_joint'/>
      <frame name='imu_joint' attached_to='base_link'>
        <pose>0.13613 -0.002005 -0.00806 0 -0 0</pose>
      </frame>
      <frame name='imu_link' attached_to='imu_joint'/>
      <frame name='lidar_joint' attached_to='base_link'>
        <pose>0.081426 0.001654 0.010345 0 -0.002402 0.000145</pose>
      </frame>
      <frame name='lidar_link' attached_to='lidar_joint'/>
      <pose>0 0 0.1 0 -0 0</pose>
    </model>
    <model name='edit_world'>
      <pose>2.21794 -1.13682 0 0 -0 0</pose>
      <link name='Wall_10'>
        <collision name='Wall_10_Collision'>
          <geometry>
            <box>
              <size>6.81013 0.15 2.5</size>
            </box>
          </geometry>
          <pose>0 0 1.25 0 -0 0</pose>
          <max_contacts>10</max_contacts>
          <surface>
            <contact>
              <ode/>
            </contact>
            <bounce/>
            <friction>
              <torsional>
                <ode/>
              </torsional>
              <ode/>
            </friction>
          </surface>
        </collision>
        <visual name='Wall_10_Visual'>
          <pose>0 0 1.25 0 -0 0</pose>
          <geometry>
            <box>
              <size>6.81013 0.15 2.5</size>
            </box>
          </geometry>
          <material>
            <script>
              <uri>file://media/materials/scripts/gazebo.material</uri>
              <name>Gazebo/Wood</name>
            </script>
            <ambient>1 1 1 1</ambient>
          </material>
          <meta>
            <layer>0</layer>
          </meta>
        </visual>
        <pose>4.87217 0.012105 0 0 -0 1.5708</pose>
        <self_collide>0</self_collide>
        <enable_wind>0</enable_wind>
        <kinematic>0</kinematic>
      </link>
      <link name='Wall_11'>
        <pose>0.052056 3.34216 0 0 -0 3.14159</pose>
        <visual name='Wall_11_Visual_0'>
          <pose>-0.7275 0 1.25 0 -0 0</pose>
          <geometry>
            <box>
              <size>8.295 0.15 2.5</size>
            </box>
          </geometry>
          <material>
            <script>
              <uri>file://media/materials/scripts/gazebo.material</uri>
              <name>Gazebo/Wood</name>
            </script>
            <ambient>1 1 1 1</ambient>
          </material>
          <meta>
            <layer>0</layer>
          </meta>
        </visual>
        <collision name='Wall_11_Collision_0'>
          <geometry>
            <box>
              <size>8.295 0.15 2.5</size>
            </box>
          </geometry>
          <pose>-0.7275 0 1.25 0 -0 0</pose>
          <max_contacts>10</max_contacts>
          <surface>
            <contact>
              <ode/>
            </contact>
            <bounce/>
            <friction>
              <torsional>
                <ode/>
              </torsional>
              <ode/>
            </friction>
          </surface>
        </collision>
        <visual name='Wall_11_Visual_1'>
          <pose>4.1475 0 0.25 0 -0 0</pose>
          <geometry>
            <box>
              <size>1.455 0.15 0.5</size>
            </box>
          </geometry>
          <material>
            <script>
              <uri>file://media/materials/scripts/gazebo.material</uri>
              <name>Gazebo/Wood</name>
            </script>
            <ambient>1 1 1 1</ambient>
          </material>
          <meta>
            <layer>0</layer>
          </meta>
        </visual>
        <collision name='Wall_11_Collision_1'>
          <geometry>
            <box>
              <size>1.455 0.15 0.5</size>
            </box>
          </geometry>
          <pose>4.1475 0 0.25 0 -0 0</pose>
          <max_contacts>10</max_contacts>
          <surface>
            <contact>
              <ode/>
            </contact>
            <bounce/>
            <friction>
              <torsional>
                <ode/>
              </torsional>
              <ode/>
            </friction>
          </surface>
        </collision>
        <visual name='Wall_11_Visual_2'>
          <pose>4.5475 0 1.5 0 -0 0</pose>
          <geometry>
            <box>
              <size>0.655 0.15 2</size>
            </box>
          </geometry>
          <material>
            <script>
              <uri>file://media/materials/scripts/gazebo.material</uri>
              <name>Gazebo/Wood</name>
            </script>
            <ambient>1 1 1 1</ambient>
          </material>
          <meta>
            <layer>0</layer>
          </meta>
        </visual>
        <collision name='Wall_11_Collision_2'>
          <geometry>
            <box>
              <size>0.655 0.15 2</size>
            </box>
          </geometry>
          <pose>4.5475 0 1.5 0 -0 0</pose>
          <max_contacts>10</max_contacts>
          <surface>
            <contact>
              <ode/>
            </contact>
            <bounce/>
            <friction>
              <torsional>
                <ode/>
              </torsional>
              <ode/>
            </friction>
          </surface>
        </collision>
        <visual name='Wall_11_Visual_3'>
          <pose>3.82 0 1.9 0 -0 0</pose>
          <geometry>
            <box>
              <size>0.8 0.15 1.2</size>
            </box>
          </geometry>
          <material>
            <script>
              <uri>file://media/materials/scripts/gazebo.material</uri>
              <name>Gazebo/Wood</name>
            </script>
            <ambient>1 1 1 1</ambient>
          </material>
          <meta>
            <layer>0</layer>
          </meta>
        </visual>
        <collision name='Wall_11_Collision_3'>
          <geometry>
            <box>
              <size>0.8 0.15 1.2</size>
            </box>
          </geometry>
          <pose>3.82 0 1.9 0 -0 0</pose>
          <max_contacts>10</max_contacts>
          <surface>
            <contact>
              <ode/>
            </contact>
            <bounce/>
            <friction>
              <torsional>
                <ode/>
              </torsional>
              <ode/>
            </friction>
          </surface>
        </collision>
        <self_collide>0</self_collide>
        <enable_wind>0</enable_wind>
        <kinematic>0</kinematic>
      </link>
      <link name='Wall_13'>
        <collision name='Wall_13_Collision'>
          <geometry>
            <box>
              <size>1.5 0.15 2.5</size>
            </box>
          </geometry>
          <pose>0 0 1.25 0 -0 0</pose>
          <max_contacts>10</max_contacts>
          <surface>
            <contact>
              <ode/>
            </contact>
            <bounce/>
            <friction>
              <torsional>
                <ode/>
              </torsional>
              <ode/>
            </friction>
          </surface>
        </collision>
        <visual name='Wall_13_Visual'>
          <pose>0 0 1.25 0 -0 0</pose>
          <geometry>
            <box>
              <size>1.5 0.15 2.5</size>
            </box>
          </geometry>
          <material>
            <script>
              <uri>file://media/materials/scripts/gazebo.material</uri>
              <name>Gazebo/Wood</name>
            </script>
            <ambient>1 1 1 1</ambient>
          </material>
          <meta>
            <layer>0</layer>
          </meta>
        </visual>
        <pose>0.692056 -0.738176 0 0 -0 -1.5708</pose>
        <self_collide>0</self_collide>
        <enable_wind>0</enable_wind>
        <kinematic>0</kinematic>
      </link>
      <link name='Wall_14'>
        <collision name='Wall_14_Collision'>
          <geometry>
            <box>
              <size>1.5 0.15 2.5</size>
            </box>
          </geometry>
          <pose>0 0 1.25 0 -0 0</pose>
          <max_contacts>10</max_contacts>
          <surface>
            <contact>
              <ode/>
            </contact>
            <bounce/>
            <friction>
              <torsional>
                <ode/>
              </torsional>
              <ode/>
            </friction>
          </surface>
        </collision>
        <visual name='Wall_14_Visual'>
          <pose>0 0 1.25 0 -0 0</pose>
          <geometry>
            <box>
              <size>1.5 0.15 2.5</size>
            </box>
          </geometry>
          <material>
            <script>
              <uri>file://media/materials/scripts/gazebo.material</uri>
              <name>Gazebo/Wood</name>
            </script>
            <ambient>1 1 1 1</ambient>
          </material>
          <meta>
            <layer>0</layer>
          </meta>
        </visual>
        <pose>0.017056 -1.41318 0 0 -0 3.14159</pose>
        <self_collide>0</self_collide>
        <enable_wind>0</enable_wind>
        <kinematic>0</kinematic>
      </link>
      <link name='Wall_4'>
        <collision name='Wall_4_Collision'>
          <geometry>
            <box>
              <size>2.20206 0.15 2.5</size>
            </box>
          </geometry>
          <pose>0 0 1.25 0 -0 0</pose>
          <max_contacts>10</max_contacts>
          <surface>
            <contact>
              <ode/>
            </contact>
            <bounce/>
            <friction>
              <torsional>
                <ode/>
              </torsional>
              <ode/>
            </friction>
          </surface>
        </collision>
        <visual name='Wall_4_Visual'>
          <pose>0 0 1.25 0 -0 0</pose>
          <geometry>
            <box>
              <size>2.20206 0.15 2.5</size>
            </box>
          </geometry>
          <material>
            <script>
              <uri>file://media/materials/scripts/gazebo.material</uri>
              <name>Gazebo/Wood</name>
            </script>
            <ambient>1 1 1 1</ambient>
          </material>
          <meta>
            <layer>0</layer>
          </meta>
        </visual>
        <pose>-3.91289 -2.89556 0 0 -0 -0.424284</pose>
        <self_collide>0</self_collide>
        <enable_wind>0</enable_wind>
        <kinematic>0</kinematic>
      </link>
      <link name='Wall_7'>
        <collision name='Wall_7_Collision'>
          <geometry>
            <box>
              <size>1.25 0.15 2.5</size>
            </box>
          </geometry>
          <pose>0 0 1.25 0 -0 0</pose>
          <max_contacts>10</max_contacts>
          <surface>
            <contact>
              <ode/>
            </contact>
            <bounce/>
            <friction>
              <torsional>
                <ode/>
              </torsional>
              <ode/>
            </friction>
          </surface>
        </collision>
        <visual name='Wall_7_Visual'>
          <pose>0 0 1.25 0 -0 0</pose>
          <geometry>
            <box>
              <size>1.25 0.15 2.5</size>
            </box>
          </geometry>
          <material>
            <script>
              <uri>file://media/materials/scripts/gazebo.material</uri>
              <name>Gazebo/Wood</name>
            </script>
            <ambient>1 1 1 1</ambient>
          </material>
          <meta>
            <layer>0</layer>
          </meta>
        </visual>
        <pose>-4.84794 -1.92318 0 0 -0 -1.5708</pose>
        <self_collide>0</self_collide>
        <enable_wind>0</enable_wind>
        <kinematic>0</kinematic>
      </link>
      <link name='Wall_9'>
        <collision name='Wall_9_Collision'>
          <geometry>
            <box>
              <size>8 0.15 2.5</size>
            </box>
          </geometry>
          <pose>0 0 1.25 0 -0 0</pose>
          <max_contacts>10</max_contacts>
          <surface>
            <contact>
              <ode/>
            </contact>
            <bounce/>
            <friction>
              <torsional>
                <ode/>
              </torsional>
              <ode/>
            </friction>
          </surface>
        </collision>
        <visual name='Wall_9_Visual'>
          <pose>0 0 1.25 0 -0 0</pose>
          <geometry>
            <box>
              <size>8 0.15 2.5</size>
            </box>
          </geometry>
          <material>
            <script>
              <uri>file://media/materials/scripts/gazebo.material</uri>
              <name>Gazebo/Wood</name>
            </script>
            <ambient>1 1 1 1</ambient>
          </material>
          <meta>
            <layer>0</layer>
          </meta>
        </visual>
        <pose>0.947169 -3.33806 0 0 -0 0</pose>
        <self_collide>0</self_collide>
        <enable_wind>0</enable_wind>
        <kinematic>0</kinematic>
      </link>
      <static>1</static>
    </model>
    <state world_name='default'>
      <sim_time>63 494000000</sim_time>
      <real_time>133 137922137</real_time>
      <wall_time>1743467755 752493203</wall_time>
      <iterations>34045</iterations>
      <model name='edit_world'>
        <pose>2.21794 -1.13681 0 0 -0 0</pose>
        <scale>1 1 1</scale>
        <link name='Wall_10'>
          <pose>7.09011 -1.12471 0 0 -0 1.5708</pose>
          <velocity>0 0 0 0 -0 0</velocity>
          <acceleration>0 0 0 0 -0 0</acceleration>
          <wrench>0 0 0 0 -0 0</wrench>
        </link>
        <link name='Wall_11'>
          <pose>2.27 2.20534 0 0 -0 3.14159</pose>
          <velocity>0 0 0 0 -0 0</velocity>
          <acceleration>0 0 0 0 -0 0</acceleration>
          <wrench>0 0 0 0 -0 0</wrench>
        </link>
        <link name='Wall_13'>
          <pose>2.91 -1.875 0 0 0 -1.5708</pose>
          <velocity>0 0 0 0 -0 0</velocity>
          <acceleration>0 0 0 0 -0 0</acceleration>
          <wrench>0 0 0 0 -0 0</wrench>
        </link>
        <link name='Wall_14'>
          <pose>2.235 -2.55 0 0 -0 3.14159</pose>
          <velocity>0 0 0 0 -0 0</velocity>
          <acceleration>0 0 0 0 -0 0</acceleration>
          <wrench>0 0 0 0 -0 0</wrench>
        </link>
        <link name='Wall_4'>
          <pose>-1.69495 -4.03238 0 0 0 -0.424284</pose>
          <velocity>0 0 0 0 -0 0</velocity>
          <acceleration>0 0 0 0 -0 0</acceleration>
          <wrench>0 0 0 0 -0 0</wrench>
        </link>
        <link name='Wall_7'>
          <pose>-2.63 -3.06 0 0 0 -1.5708</pose>
          <velocity>0 0 0 0 -0 0</velocity>
          <acceleration>0 0 0 0 -0 0</acceleration>
          <wrench>0 0 0 0 -0 0</wrench>
        </link>
        <link name='Wall_9'>
          <pose>3.16511 -4.47488 0 0 -0 0</pose>
          <velocity>0 0 0 0 -0 0</velocity>
          <acceleration>0 0 0 0 -0 0</acceleration>
          <wrench>0 0 0 0 -0 0</wrench>
        </link>
      </model>
      <model name='ground_plane'>
        <pose>0 0 0 0 -0 0</pose>
        <scale>1 1 1</scale>
        <link name='link'>
          <pose>0 0 0 0 -0 0</pose>
          <velocity>0 0 0 0 -0 0</velocity>
          <acceleration>0 0 0 0 -0 0</acceleration>
          <wrench>0 0 0 0 -0 0</wrench>
        </link>
      </model>
      <model name='robot_model_final'>
        <pose>0.008974 -0.115576 0.127888 -0.005571 0.002808 0.106209</pose>
        <scale>1 1 1</scale>
        <link name='arm_link_1'>
          <pose>0.009904 -0.124357 0.141936 1.56525 0.002979 0.106174</pose>
          <velocity>-0.0002 -0.002967 0.004628 0.004646 0.005353 -0.02964</velocity>
          <acceleration>-0.151112 0.990423 9.56538 -0.625578 0.378944 -2.88001</acceleration>
          <wrench>-0.001523 0.009982 0.096403 0 -0 0</wrench>
        </link>
        <link name='arm_link_2'>
          <pose>-0.014095 -0.106236 0.239379 1.5652 0.003032 0.106206</pose>
          <velocity>4.1e-05 -0.00289 0.003947 -0.012238 -0.002791 -0.016698</velocity>
          <acceleration>-1.18073 -0.711153 8.49441 -1.55163 0.429528 -0.692076</acceleration>
          <wrench>-0.028553 -0.017197 0.205414 0 -0 0</wrench>
        </link>
        <link name='base_link'>
          <pose>0.008974 -0.115576 0.127888 -0.005571 0.002808 0.106209</pose>
          <velocity>0.000218 -0.002953 0.004884 -0.003687 -0.000244 0.003094</velocity>
          <acceleration>-0.155804 0.16774 9.92973 -2.03615 0.009602 0.515579</acceleration>
          <wrench>-0.782399 0.842335 49.8639 0 -0 0</wrench>
        </link>
        <link name='l1_link'>
          <pose>-0.062218 -0.316387 0.060004 1.56541 -0.175495 0.107146</pose>
          <velocity>0.000856 -0.003327 0.007624 0.05392 0.015806 -0.001965</velocity>
          <acceleration>0.208256 0.080076 18.9585 0.030723 0.7513 -2.68818</acceleration>
          <wrench>0.416511 0.160152 37.917 0 -0 0</wrench>
        </link>
        <link name='l2_link'>
          <pose>0.120852 -0.296867 0.059904 1.56452 0.552213 0.102969</pose>
          <velocity>0.000537 -0.002802 0.002888 0.046747 0.007164 0.002205</velocity>
          <acceleration>-0.060855 0.136354 8.37862 0.563752 -1.47443 2.05125</acceleration>
          <wrench>-0.12171 0.272707 16.7572 0 -0 0</wrench>
        </link>
        <link name='r1_link'>
          <pose>-0.102877 0.064946 0.05785 1.56435 -0.507973 0.109357</pose>
          <velocity>-0.000172 -0.003511 0.002629 -0.016573 -0.005856 0.002474</velocity>
          <acceleration>0.007493 -0.089577 6.39433 -2.03224 -0.580248 -0.40596</acceleration>
          <wrench>0.014987 -0.179154 12.7887 0 -0 0</wrench>
        </link>
        <link name='r2_link'>
          <pose>0.080192 0.084465 0.057797 1.56537 0.196633 0.105146</pose>
          <velocity>7.6e-05 -0.002946 0.007184 0.051123 -5.5e-05 -0.002658</velocity>
          <acceleration>0.232855 -0.103415 11.0019 0.389411 -1.08721 3.12451</acceleration>
          <wrench>0.46571 -0.206831 22.0038 0 -0 0</wrench>
        </link>
      </model>
      <model name='unit_box'>
        <pose>4.44469 0.611881 0.863574 -1e-06 -0 -0.001299</pose>
        <scale>0.546167 0.552111 1.72715</scale>
        <link name='link'>
          <pose>4.44469 0.611881 0.863574 -1e-06 -0 -0.001299</pose>
          <velocity>0 0 0 0 -0 0</velocity>
          <acceleration>1.77142 -3.19403 2.36879 0.479001 0.910078 -3.10243</acceleration>
          <wrench>1.77142 -3.19403 2.36879 0 -0 0</wrench>
        </link>
      </model>
      <light name='sun'>
        <pose>0 0 10 0 -0 0</pose>
      </light>
    </state>
    <gui fullscreen='0'>
      <camera name='user_camera'>
        <pose>-12.2073 0.933689 4.00469 0 0.349799 0.000213</pose>
        <view_controller>orbit</view_controller>
        <projection_type>perspective</projection_type>
      </camera>
    </gui>
    <model name='unit_box'>
      <pose>4.44455 0.611489 0.5 0 -0 0</pose>
      <link name='link'>
        <inertial>
          <mass>1</mass>
          <inertia>
            <ixx>0.166667</ixx>
            <ixy>0</ixy>
            <ixz>0</ixz>
            <iyy>0.166667</iyy>
            <iyz>0</iyz>
            <izz>0.166667</izz>
          </inertia>
          <pose>0 0 0 0 -0 0</pose>
        </inertial>
        <collision name='collision'>
          <geometry>
            <box>
              <size>1 1 1</size>
            </box>
          </geometry>
          <max_contacts>10</max_contacts>
          <surface>
            <contact>
              <ode/>
            </contact>
            <bounce/>
            <friction>
              <torsional>
                <ode/>
              </torsional>
              <ode/>
            </friction>
          </surface>
        </collision>
        <visual name='visual'>
          <geometry>
            <box>
              <size>1 1 1</size>
            </box>
          </geometry>
          <material>
            <script>
              <name>Gazebo/Grey</name>
              <uri>file://media/materials/scripts/gazebo.material</uri>
            </script>
          </material>
        </visual>
        <self_collide>0</self_collide>
        <enable_wind>0</enable_wind>
        <kinematic>0</kinematic>
      </link>
    </model>
  </world>
</sdf>
